Client 0 started on port 2222.
Client WebSocket: ID: 0:  Connection Accepted!
Client WebSocket: ID: 0:  Message: {"message":"job-info","job":{"algorithm":"1d_categorical_histogram","attributes":[{"name":"G07.100.100.160.120.699.500"}],"filters":[null],"dataProviders":[0,1,2],"id":"0fcf639d-26b3-4eb8-9d43-594c775f87d7","timestamps":{"accepted":1566834565984,"process":1566834565989},"status":1,"totalClients":3}}
Client WebSocket: ID: 0:  Message: {"message":"data-info","job":{"algorithm":"1d_categorical_histogram","attributes":[{"name":"G07.100.100.160.120.699.500"}],"filters":[null],"dataProviders":[0,1,2],"id":"0fcf639d-26b3-4eb8-9d43-594c775f87d7","timestamps":{"accepted":1566834565984,"process":1566834565989},"status":1,"totalClients":3}}
Traceback (most recent call last):
  File "/usr/local/lib/python3.5/dist-packages/urllib3/connection.py", line 160, in _new_conn
    (self._dns_host, self.port), self.timeout, **extra_kw)
  File "/usr/local/lib/python3.5/dist-packages/urllib3/util/connection.py", line 57, in create_connection
    for res in socket.getaddrinfo(host, port, family, socket.SOCK_STREAM):
  File "/usr/lib/python3.5/socket.py", line 733, in getaddrinfo
    for res in _socket.getaddrinfo(host, port, family, type, proto, flags):
socket.gaierror: [Errno -2] Name or service not known

During handling of the above exception, another exception occurred:

Traceback (most recent call last):
  File "/usr/local/lib/python3.5/dist-packages/urllib3/connectionpool.py", line 603, in urlopen
    chunked=chunked)
  File "/usr/local/lib/python3.5/dist-packages/urllib3/connectionpool.py", line 344, in _make_request
    self._validate_conn(conn)
  File "/usr/local/lib/python3.5/dist-packages/urllib3/connectionpool.py", line 843, in _validate_conn
    conn.connect()
  File "/usr/local/lib/python3.5/dist-packages/urllib3/connection.py", line 316, in connect
    conn = self._new_conn()
  File "/usr/local/lib/python3.5/dist-packages/urllib3/connection.py", line 169, in _new_conn
    self, "Failed to establish a new connection: %s" % e)
urllib3.exceptions.NewConnectionError: <urllib3.connection.VerifiedHTTPSConnection object at 0x7f95fc3a4710>: Failed to establish a new connection: [Errno -2] Name or service not known

During handling of the above exception, another exception occurred:

Traceback (most recent call last):
  File "/usr/local/lib/python3.5/dist-packages/requests/adapters.py", line 449, in send
    timeout=timeout
  File "/usr/local/lib/python3.5/dist-packages/urllib3/connectionpool.py", line 641, in urlopen
    _stacktrace=sys.exc_info()[2])
  File "/usr/local/lib/python3.5/dist-packages/urllib3/util/retry.py", line 399, in increment
    raise MaxRetryError(_pool, url, error or ResponseError(cause))
urllib3.exceptions.MaxRetryError: HTTPSConnectionPool(host='mhmd-local-catalgue.gnubila.fr', port=443): Max retries exceeded with url: /catalogue/search (Caused by NewConnectionError('<urllib3.connection.VerifiedHTTPSConnection object at 0x7f95fc3a4710>: Failed to establish a new connection: [Errno -2] Name or service not known',))

During handling of the above exception, another exception occurred:

Traceback (most recent call last):
  File "/smpc-local-drive/scripts/preprocessor.py", line 86, in <module>
    main()
  File "/smpc-local-drive/scripts/preprocessor.py", line 82, in main
    preprocess(args)
  File "/smpc-local-drive/scripts/preprocessor.py", line 31, in preprocess
    processor.process()
  File "/smpc-local-drive/scripts/algorithms.py", line 19, in process
    return self._strategy.process()
  File "/smpc-local-drive/scripts/algorithms.py", line 110, in preprocess
    self._dataset = self._provider.get_dataset(self.get_attributes_by_key('name'), request)
  File "/smpc-local-drive/scripts/data_providers.py", line 60, in get_dataset
    records = self.get_catalogue_records(data)
  File "/smpc-local-drive/scripts/data_providers.py", line 23, in get_catalogue_records
    res = requests.post(url=CATALOGUE_SEARCH_URL, data=data, headers={'accept': 'application/json', 'Content-Type': 'application/x-www-form-urlencoded'})
  File "/usr/local/lib/python3.5/dist-packages/requests/api.py", line 116, in post
    return request('post', url, data=data, json=json, **kwargs)
  File "/usr/local/lib/python3.5/dist-packages/requests/api.py", line 60, in request
    return session.request(method=method, url=url, **kwargs)
  File "/usr/local/lib/python3.5/dist-packages/requests/sessions.py", line 533, in request
    resp = self.send(prep, **send_kwargs)
  File "/usr/local/lib/python3.5/dist-packages/requests/sessions.py", line 646, in send
    r = adapter.send(request, **kwargs)
  File "/usr/local/lib/python3.5/dist-packages/requests/adapters.py", line 516, in send
    raise ConnectionError(e, request=request)
requests.exceptions.ConnectionError: HTTPSConnectionPool(host='mhmd-local-catalgue.gnubila.fr', port=443): Max retries exceeded with url: /catalogue/search (Caused by NewConnectionError('<urllib3.connection.VerifiedHTTPSConnection object at 0x7f95fc3a4710>: Failed to establish a new connection: [Errno -2] Name or service not known',))

Client WebSocket: ID: 0:  Message: {"message":"restart","job":{"algorithm":"1d_categorical_histogram","attributes":[{"name":"G07.100.100.160.120.699.500"}],"filters":[null],"dataProviders":[0,1,2],"id":"0fcf639d-26b3-4eb8-9d43-594c775f87d7","timestamps":{"accepted":1566834565984,"process":1566834565989},"status":1,"totalClients":3}}
Client WebSocket: ID: 0:  Connection Accepted!
Client WebSocket: ID: 0:  Message: {"message":"job-info","job":{"algorithm":"1d_categorical_histogram","attributes":[{"name":"G07.100.100.160.120.699.500"}],"filters":[null],"dataProviders":[0,1,2],"id":"0bd2b149-4d61-486f-afd3-87e2938036fc","timestamps":{"accepted":1566834578358,"process":1566834578364},"status":1,"totalClients":3}}
Client WebSocket: ID: 0:  Message: {"message":"data-info","job":{"algorithm":"1d_categorical_histogram","attributes":[{"name":"G07.100.100.160.120.699.500"}],"filters":[null],"dataProviders":[0,1,2],"id":"0bd2b149-4d61-486f-afd3-87e2938036fc","timestamps":{"accepted":1566834578358,"process":1566834578364},"status":1,"totalClients":3}}
Traceback (most recent call last):
  File "/usr/local/lib/python3.5/dist-packages/urllib3/connection.py", line 160, in _new_conn
    (self._dns_host, self.port), self.timeout, **extra_kw)
  File "/usr/local/lib/python3.5/dist-packages/urllib3/util/connection.py", line 57, in create_connection
    for res in socket.getaddrinfo(host, port, family, socket.SOCK_STREAM):
  File "/usr/lib/python3.5/socket.py", line 733, in getaddrinfo
    for res in _socket.getaddrinfo(host, port, family, type, proto, flags):
socket.gaierror: [Errno -2] Name or service not known

During handling of the above exception, another exception occurred:

Traceback (most recent call last):
  File "/usr/local/lib/python3.5/dist-packages/urllib3/connectionpool.py", line 603, in urlopen
    chunked=chunked)
  File "/usr/local/lib/python3.5/dist-packages/urllib3/connectionpool.py", line 344, in _make_request
    self._validate_conn(conn)
  File "/usr/local/lib/python3.5/dist-packages/urllib3/connectionpool.py", line 843, in _validate_conn
    conn.connect()
  File "/usr/local/lib/python3.5/dist-packages/urllib3/connection.py", line 316, in connect
    conn = self._new_conn()
  File "/usr/local/lib/python3.5/dist-packages/urllib3/connection.py", line 169, in _new_conn
    self, "Failed to establish a new connection: %s" % e)
urllib3.exceptions.NewConnectionError: <urllib3.connection.VerifiedHTTPSConnection object at 0x7f8d1ae664e0>: Failed to establish a new connection: [Errno -2] Name or service not known

During handling of the above exception, another exception occurred:

Traceback (most recent call last):
  File "/usr/local/lib/python3.5/dist-packages/requests/adapters.py", line 449, in send
    timeout=timeout
  File "/usr/local/lib/python3.5/dist-packages/urllib3/connectionpool.py", line 641, in urlopen
    _stacktrace=sys.exc_info()[2])
  File "/usr/local/lib/python3.5/dist-packages/urllib3/util/retry.py", line 399, in increment
    raise MaxRetryError(_pool, url, error or ResponseError(cause))
urllib3.exceptions.MaxRetryError: HTTPSConnectionPool(host='mhmd-local-catalgue.gnubila.fr', port=443): Max retries exceeded with url: /catalogue/search (Caused by NewConnectionError('<urllib3.connection.VerifiedHTTPSConnection object at 0x7f8d1ae664e0>: Failed to establish a new connection: [Errno -2] Name or service not known',))

During handling of the above exception, another exception occurred:

Traceback (most recent call last):
  File "/smpc-local-drive/scripts/preprocessor.py", line 86, in <module>
    main()
  File "/smpc-local-drive/scripts/preprocessor.py", line 82, in main
    preprocess(args)
  File "/smpc-local-drive/scripts/preprocessor.py", line 31, in preprocess
    processor.process()
  File "/smpc-local-drive/scripts/algorithms.py", line 19, in process
    return self._strategy.process()
  File "/smpc-local-drive/scripts/algorithms.py", line 110, in preprocess
    self._dataset = self._provider.get_dataset(self.get_attributes_by_key('name'), request)
  File "/smpc-local-drive/scripts/data_providers.py", line 60, in get_dataset
    records = self.get_catalogue_records(data)
  File "/smpc-local-drive/scripts/data_providers.py", line 23, in get_catalogue_records
    res = requests.post(url=CATALOGUE_SEARCH_URL, data=data, headers={'accept': 'application/json', 'Content-Type': 'application/x-www-form-urlencoded'})
  File "/usr/local/lib/python3.5/dist-packages/requests/api.py", line 116, in post
    return request('post', url, data=data, json=json, **kwargs)
  File "/usr/local/lib/python3.5/dist-packages/requests/api.py", line 60, in request
    return session.request(method=method, url=url, **kwargs)
  File "/usr/local/lib/python3.5/dist-packages/requests/sessions.py", line 533, in request
    resp = self.send(prep, **send_kwargs)
  File "/usr/local/lib/python3.5/dist-packages/requests/sessions.py", line 646, in send
    r = adapter.send(request, **kwargs)
  File "/usr/local/lib/python3.5/dist-packages/requests/adapters.py", line 516, in send
    raise ConnectionError(e, request=request)
requests.exceptions.ConnectionError: HTTPSConnectionPool(host='mhmd-local-catalgue.gnubila.fr', port=443): Max retries exceeded with url: /catalogue/search (Caused by NewConnectionError('<urllib3.connection.VerifiedHTTPSConnection object at 0x7f8d1ae664e0>: Failed to establish a new connection: [Errno -2] Name or service not known',))

Client WebSocket: ID: 0:  Message: {"message":"restart","job":{"algorithm":"1d_categorical_histogram","attributes":[{"name":"G07.100.100.160.120.699.500"}],"filters":[null],"dataProviders":[0,1,2],"id":"0bd2b149-4d61-486f-afd3-87e2938036fc","timestamps":{"accepted":1566834578358,"process":1566834578364},"status":1,"totalClients":3}}
Client WebSocket: ID: 0:  Connection Accepted!
Client WebSocket: ID: 0:  Message: {"message":"job-info","job":{"algorithm":"1d_categorical_histogram","attributes":[{"name":"G07.100.100.160.120.699.500"}],"filters":[null],"dataProviders":[0],"id":"603dbb34-db5d-4ac5-8b8a-d0d808b3a1b6","timestamps":{"accepted":1566835263574,"process":1566835263578},"status":1,"totalClients":1}}
Client WebSocket: ID: 0:  Message: {"message":"data-info","job":{"algorithm":"1d_categorical_histogram","attributes":[{"name":"G07.100.100.160.120.699.500"}],"filters":[null],"dataProviders":[0],"id":"603dbb34-db5d-4ac5-8b8a-d0d808b3a1b6","timestamps":{"accepted":1566835263574,"process":1566835263578},"status":1,"totalClients":1}}
Traceback (most recent call last):
  File "/usr/local/lib/python3.5/dist-packages/urllib3/connection.py", line 160, in _new_conn
    (self._dns_host, self.port), self.timeout, **extra_kw)
  File "/usr/local/lib/python3.5/dist-packages/urllib3/util/connection.py", line 57, in create_connection
    for res in socket.getaddrinfo(host, port, family, socket.SOCK_STREAM):
  File "/usr/lib/python3.5/socket.py", line 733, in getaddrinfo
    for res in _socket.getaddrinfo(host, port, family, type, proto, flags):
socket.gaierror: [Errno -2] Name or service not known

During handling of the above exception, another exception occurred:

Traceback (most recent call last):
  File "/usr/local/lib/python3.5/dist-packages/urllib3/connectionpool.py", line 603, in urlopen
    chunked=chunked)
  File "/usr/local/lib/python3.5/dist-packages/urllib3/connectionpool.py", line 344, in _make_request
    self._validate_conn(conn)
  File "/usr/local/lib/python3.5/dist-packages/urllib3/connectionpool.py", line 843, in _validate_conn
    conn.connect()
  File "/usr/local/lib/python3.5/dist-packages/urllib3/connection.py", line 316, in connect
    conn = self._new_conn()
  File "/usr/local/lib/python3.5/dist-packages/urllib3/connection.py", line 169, in _new_conn
    self, "Failed to establish a new connection: %s" % e)
urllib3.exceptions.NewConnectionError: <urllib3.connection.VerifiedHTTPSConnection object at 0x7f61d4e5c4e0>: Failed to establish a new connection: [Errno -2] Name or service not known

During handling of the above exception, another exception occurred:

Traceback (most recent call last):
  File "/usr/local/lib/python3.5/dist-packages/requests/adapters.py", line 449, in send
    timeout=timeout
  File "/usr/local/lib/python3.5/dist-packages/urllib3/connectionpool.py", line 641, in urlopen
    _stacktrace=sys.exc_info()[2])
  File "/usr/local/lib/python3.5/dist-packages/urllib3/util/retry.py", line 399, in increment
    raise MaxRetryError(_pool, url, error or ResponseError(cause))
urllib3.exceptions.MaxRetryError: HTTPSConnectionPool(host='mhmd-local-catalgue.gnubila.fr', port=443): Max retries exceeded with url: /catalogue/search (Caused by NewConnectionError('<urllib3.connection.VerifiedHTTPSConnection object at 0x7f61d4e5c4e0>: Failed to establish a new connection: [Errno -2] Name or service not known',))

During handling of the above exception, another exception occurred:

Traceback (most recent call last):
  File "/smpc-local-drive/scripts/preprocessor.py", line 86, in <module>
    main()
  File "/smpc-local-drive/scripts/preprocessor.py", line 82, in main
    preprocess(args)
  File "/smpc-local-drive/scripts/preprocessor.py", line 31, in preprocess
    processor.process()
  File "/smpc-local-drive/scripts/algorithms.py", line 19, in process
    return self._strategy.process()
  File "/smpc-local-drive/scripts/algorithms.py", line 110, in preprocess
    self._dataset = self._provider.get_dataset(self.get_attributes_by_key('name'), request)
  File "/smpc-local-drive/scripts/data_providers.py", line 60, in get_dataset
    records = self.get_catalogue_records(data)
  File "/smpc-local-drive/scripts/data_providers.py", line 23, in get_catalogue_records
    res = requests.post(url=CATALOGUE_SEARCH_URL, data=data, headers={'accept': 'application/json', 'Content-Type': 'application/x-www-form-urlencoded'})
  File "/usr/local/lib/python3.5/dist-packages/requests/api.py", line 116, in post
    return request('post', url, data=data, json=json, **kwargs)
  File "/usr/local/lib/python3.5/dist-packages/requests/api.py", line 60, in request
    return session.request(method=method, url=url, **kwargs)
  File "/usr/local/lib/python3.5/dist-packages/requests/sessions.py", line 533, in request
    resp = self.send(prep, **send_kwargs)
  File "/usr/local/lib/python3.5/dist-packages/requests/sessions.py", line 646, in send
    r = adapter.send(request, **kwargs)
  File "/usr/local/lib/python3.5/dist-packages/requests/adapters.py", line 516, in send
    raise ConnectionError(e, request=request)
requests.exceptions.ConnectionError: HTTPSConnectionPool(host='mhmd-local-catalgue.gnubila.fr', port=443): Max retries exceeded with url: /catalogue/search (Caused by NewConnectionError('<urllib3.connection.VerifiedHTTPSConnection object at 0x7f61d4e5c4e0>: Failed to establish a new connection: [Errno -2] Name or service not known',))

Client WebSocket: ID: 0:  Message: {"message":"restart","job":{"algorithm":"1d_categorical_histogram","attributes":[{"name":"G07.100.100.160.120.699.500"}],"filters":[null],"dataProviders":[0],"id":"603dbb34-db5d-4ac5-8b8a-d0d808b3a1b6","timestamps":{"accepted":1566835263574,"process":1566835263578},"status":1,"totalClients":1}}
